Unhandled exception in thread started by <function check_errors.<locals>.wrapper at 0x7f71bcde49d8>
Traceback (most recent call last):
  File "/usr/local/lib/python3.6/site-packages/django/utils/autoreload.py", line 225, in wrapper
    fn(*args, **kwargs)
  File "/usr/local/lib/python3.6/site-packages/django/core/management/commands/runserver.py", line 117, in inner_run
    self.check(display_num_errors=True)
  File "/usr/local/lib/python3.6/site-packages/django/core/management/base.py", line 379, in check
    include_deployment_checks=include_deployment_checks,
  File "/usr/local/lib/python3.6/site-packages/django/core/management/base.py", line 366, in _run_checks
    return checks.run_checks(**kwargs)
  File "/usr/local/lib/python3.6/site-packages/django/core/checks/registry.py", line 71, in run_checks
    new_errors = check(app_configs=app_configs)
  File "/usr/local/lib/python3.6/site-packages/django/core/checks/urls.py", line 13, in check_url_config
    return check_resolver(resolver)
  File "/usr/local/lib/python3.6/site-packages/django/core/checks/urls.py", line 23, in check_resolver
    return check_method()
  File "/usr/local/lib/python3.6/site-packages/django/urls/resolvers.py", line 396, in check
    for pattern in self.url_patterns:
  File "/usr/local/lib/python3.6/site-packages/django/utils/functional.py", line 37, in __get__
    res = instance.__dict__[self.name] = self.func(instance)
  File "/usr/local/lib/python3.6/site-packages/django/urls/resolvers.py", line 533, in url_patterns
    patterns = getattr(self.urlconf_module, "urlpatterns", self.urlconf_module)
  File "/usr/local/lib/python3.6/site-packages/django/utils/functional.py", line 37, in __get__
    res = instance.__dict__[self.name] = self.func(instance)
  File "/usr/local/lib/python3.6/site-packages/django/urls/resolvers.py", line 526, in urlconf_module
    return import_module(self.urlconf_name)
  File "/usr/lib64/python3.6/importlib/__init__.py", line 126, in import_module
    return _bootstrap._gcd_import(name[level:], package, level)
  File "<frozen importlib._bootstrap>", line 994, in _gcd_import
  File "<frozen importlib._bootstrap>", line 971, in _find_and_load
  File "<frozen importlib._bootstrap>", line 955, in _find_and_load_unlocked
  File "<frozen importlib._bootstrap>", line 665, in _load_unlocked
  File "<frozen importlib._bootstrap_external>", line 678, in exec_module
  File "<frozen importlib._bootstrap>", line 219, in _call_with_frames_removed
  File "/root/cyr_tmp/django/dev/robo_advisor/urls.py", line 19, in <module>
    from fastback import views
  File "/root/cyr_tmp/django/dev/fastback/views.py", line 153, in <module>
    from database.db_init import data_proxy,future_proxy
  File "/root/cyr_tmp/django/dev/database/db_init.py", line 12, in <module>
    data_proxy = FactorDatabase(db_name=db_name, host_name=host_name, user_name=user, pwd=password,port=port)
  File "/root/cyr_tmp/django/dev/database/DB_Factors.py", line 17, in __init__
    self.connnect_db()
  File "/root/cyr_tmp/django/dev/database/DB_Database.py", line 17, in connnect_db
    host=self.host_name, port=self.port)
  File "/usr/local/lib64/python3.6/site-packages/psycopg2/__init__.py", line 127, in connect
    conn = _connect(dsn, connection_factory=connection_factory, **kwasync)
psycopg2.OperationalError: could not connect to server: Connection timed out
	Is the server running on host "40.73.102.25" and accepting
	TCP/IP connections on port 5432?

Performing system checks...

Factor Database init...
Unhandled exception in thread started by <function check_errors.<locals>.wrapper at 0x7fdda20aa9d8>
Traceback (most recent call last):
  File "/usr/local/lib/python3.6/site-packages/django/utils/autoreload.py", line 225, in wrapper
    fn(*args, **kwargs)
  File "/usr/local/lib/python3.6/site-packages/django/core/management/commands/runserver.py", line 117, in inner_run
    self.check(display_num_errors=True)
  File "/usr/local/lib/python3.6/site-packages/django/core/management/base.py", line 379, in check
    include_deployment_checks=include_deployment_checks,
  File "/usr/local/lib/python3.6/site-packages/django/core/management/base.py", line 366, in _run_checks
    return checks.run_checks(**kwargs)
  File "/usr/local/lib/python3.6/site-packages/django/core/checks/registry.py", line 71, in run_checks
    new_errors = check(app_configs=app_configs)
  File "/usr/local/lib/python3.6/site-packages/django/core/checks/urls.py", line 13, in check_url_config
    return check_resolver(resolver)
  File "/usr/local/lib/python3.6/site-packages/django/core/checks/urls.py", line 23, in check_resolver
    return check_method()
  File "/usr/local/lib/python3.6/site-packages/django/urls/resolvers.py", line 396, in check
    for pattern in self.url_patterns:
  File "/usr/local/lib/python3.6/site-packages/django/utils/functional.py", line 37, in __get__
    res = instance.__dict__[self.name] = self.func(instance)
  File "/usr/local/lib/python3.6/site-packages/django/urls/resolvers.py", line 533, in url_patterns
    patterns = getattr(self.urlconf_module, "urlpatterns", self.urlconf_module)
  File "/usr/local/lib/python3.6/site-packages/django/utils/functional.py", line 37, in __get__
    res = instance.__dict__[self.name] = self.func(instance)
  File "/usr/local/lib/python3.6/site-packages/django/urls/resolvers.py", line 526, in urlconf_module
    return import_module(self.urlconf_name)
  File "/usr/lib64/python3.6/importlib/__init__.py", line 126, in import_module
    return _bootstrap._gcd_import(name[level:], package, level)
  File "<frozen importlib._bootstrap>", line 994, in _gcd_import
  File "<frozen importlib._bootstrap>", line 971, in _find_and_load
  File "<frozen importlib._bootstrap>", line 955, in _find_and_load_unlocked
  File "<frozen importlib._bootstrap>", line 665, in _load_unlocked
  File "<frozen importlib._bootstrap_external>", line 678, in exec_module
  File "<frozen importlib._bootstrap>", line 219, in _call_with_frames_removed
  File "/root/cyr_tmp/django/dev/robo_advisor/urls.py", line 19, in <module>
    from fastback import views
  File "/root/cyr_tmp/django/dev/fastback/views.py", line 153, in <module>
    from database.db_init import data_proxy,future_proxy
  File "/root/cyr_tmp/django/dev/database/db_init.py", line 12, in <module>
    data_proxy = FactorDatabase(db_name=db_name, host_name=host_name, user_name=user, pwd=password,port=port)
  File "/root/cyr_tmp/django/dev/database/DB_Factors.py", line 17, in __init__
    self.connnect_db()
  File "/root/cyr_tmp/django/dev/database/DB_Database.py", line 17, in connnect_db
    host=self.host_name, port=self.port)
  File "/usr/local/lib64/python3.6/site-packages/psycopg2/__init__.py", line 127, in connect
    conn = _connect(dsn, connection_factory=connection_factory, **kwasync)
psycopg2.OperationalError: could not connect to server: Connection timed out
	Is the server running on host "40.73.102.25" and accepting
	TCP/IP connections on port 5432?

Performing system checks...

Factor Database init...
